Workbook

Sheet Cover
A1: Paket FP&A Tambang Batubara – Global Energy Group
A2: Disusun oleh FP&A | Laporan keuangan contoh, analisa struktur biaya & KPI, dan template pelaporan bulanan GEG
A4: DAFTAR ISI
A5: BAGIAN A – CONTOH LAPORAN KEUANGAN LENGKAP (perusahaan fiktif, format emiten batubara Tbk, PSAK)
A6: A1 Asumsi Contoh | B6: Asumsi & driver: harga, kurs, volume, SR, tarif kontraktor, BBM, logistik, royalti, overhead, capex, modal kerja
A7: A2 Laba Rugi Contoh | B7: Laba rugi rinci: breakdown pendapatan (ekspor/DMO/non-DMO/penalti/jasa), BPP (tambang, logistik, royalti, overhead, D&A), beban penjualan, G&A, lain-lain
A8: A3 Neraca Contoh | B8: Neraca 3 periode, terhubung dengan laba rugi & arus kas (cek keseimbangan = 0)
A9: A4 Arus Kas Contoh | B9: Arus kas metode tidak langsung + rekonsiliasi metode langsung
A10: BAGIAN B – ANALISA UNTUK MANAJEMEN
A11: B1 Struktur Rev-Cost | B11: Struktur pendapatan (bauran pasar, ASP) & struktur biaya (porsi, sifat tetap/variabel, pemicu), titik impas
A12: B2 COP dan KPI | B12: Cost of production per unit (USD/bcm, USD/t, USD/t-km, cash cost, AISC) + penilaian KPI COP dengan skor
A13: B3 KPI Cost vs Revenue | B13: 27 KPI cost vs revenue (jaws, rasio biaya, marjin, harga impas, leverage, konversi kas) + kesimpulan otomatis
A14: B4 Efisiensi Biaya | B14: Varians biaya: efek volume vs tarif vs kurs; jembatan pendapatan & EBITDA (pasar vs manajemen); inisiatif penghematan
A15: B5 Benchmark Emiten | B15: Emiten batubara BEI sebagai acuan & kisaran KPI industri (indikatif)
A16: BAGIAN C – TEMPLATE PELAPORAN BULANAN GLOBAL ENERGY GROUP
A17: C0 GEG Petunjuk | B17: Petunjuk, kode warna, jadwal closing bulanan
A18: C1 GEG Setting | B18: Pengaturan bulan laporan & skala KPI
A19: C2 GEG Ops Budget | B19: Input budget operasional bulanan
A20: C3 GEG Ops Aktual | B20: Input aktual operasional bulanan
A21: C4 GEG LR Budget | B21: Input budget laba rugi bulanan (kode akun)
A22: C5 GEG LR Aktual | B22: Input aktual laba rugi bulanan (kode akun)
A23: C6 GEG Neraca Aktual | B23: Input neraca akhir bulan
A24: C7 GEG Arus Kas | B24: Arus kas bulanan otomatis
A25: C8 GEG Lap LR | B25: Laporan laba rugi MTD & YTD vs budget
A26: C9 GEG Lap Ops | B26: Laporan operasional MTD & YTD vs budget
A27: C10 GEG COP | B27: Cost of production per unit vs budget
A28: C11 GEG KPI Scorecard | B28: KPI scorecard manajemen (skor & predikat)
A29: C12 GEG Dashboard | B29: DASHBOARD: tile KPI, 8 grafik kinerja (pendapatan, EBITDA, produksi, SR, cash cost vs ASP, fuel ratio, struktur biaya, skor perspektif) + tabel KPI Scored
A30: FORMAT LAPORAN BULANAN ALA "AAT FINANCIAL & OPERATIONAL PERFORMANCE REPORT" – disesuaikan untuk batubara
A31: C13 GEG Financial Highlight | B31: Key indicators operasional & keuangan: bulan lalu vs bulan ini (MoM), vs budget, YTD, EBITDA normalisasi, CADS, DSCR + kolom catatan
A32: C14 GEG Analisa Biaya | B32: Analisa biaya per akun & unit cost (USD/bcm, USD/t) – MoM, vs budget, YTD + catatan penjelasan varians
A33: C15 GEG Tren Volume | B33: Tren volume bulanan: aktual tahun lalu vs budget vs aktual (OB, produksi, SR, penjualan, barging, stok) + grafik
A34: C16 GEG Pit dan Pembeli | B34: Rincian produksi/OB/SR per pit & kontraktor serta penjualan per pembeli, dengan cek rekonsiliasi ke C3
A35: C17 GEG Arus Kas Langsung | B35: Arus kas metode langsung: kas operasi, debt service, CADS, capex, DSCR – aktual otomatis vs budget
A36: C18 GEG Cost per BCM dan MT | B36: Analisa COST PER BCM (OB) & COST PER MT batubara terjual: MoM, vs budget, YTD, jembatan efek tarif vs efek SR, tren bulanan + grafik
A37: REVISI MENGACU MIS AAT (Dec-23): ALUR DATA GL → MIS, COVENANT, BRIDGE & KONTROL
A38: C19 GEG GL Trial Balance | B38: INPUT UTAMA KEUANGAN: tempel trial balance GL per akun (aktual & budget) + Tag MIS; C4/C5 terisi otomatis via SUMIFS, dengan kontrol akun belum dimapping
A39: C20 GEG Covenant Bank | B39: Kepatuhan covenant bank bulanan: adjusted current ratio, debt to tangible net worth, DSCR, ICR, net debt/EBITDA → MEET / NOT MEET
A40: C21 GEG Bridge EBITDA | B40: Bridge EBITDA budget → aktual (bulan ini & YTD): efek volume, harga, kurs, tiap kelompok biaya + grafik kontribusi
A41: C22 GEG Kontrol Data | B41: Checklist kontrol & rekonsiliasi seluruh workbook → status SIAP KIRIM / BELUM SIAP
...

Sheet A1 Asumsi Contoh
A1: PT Batubara Contoh Tbk (fiktif) – Asumsi & Pemicu (Driver) Operasional
A2: Lembar input model contoh. Teks biru/sel kuning = input; hitam = rumus; hijau = tautan antar-sheet. Satuan uang: Rp juta.
A5: Parameter | B5: Satuan | C5: FY2024 | D5: FY2025 | E5: Keterangan / sumber
A6: 1. MAKRO & HARGA
A7: Kurs rata-rata | B7: Rp/USD | C7: 15850 | D7: 16250 | E7: Asumsi ilustratif, mendekati rata-rata JISDOR tahun berjalan
A8: Harga indeks acuan setara CV produk (HBA/ICI) | B8: USD/t | C8: 72 | D8: 64 | E8: Ilustratif; gunakan HBA (Kepmen ESDM) / ICI sesuai CV
A9: ASP – Ekspor (FOB/CIF) | B9: USD/t | C9: 70 | D9: 62 | E9: Harga realisasi rata-rata tertimbang
A10: ASP – Domestik DMO (kelistrikan/PLN) | B10: USD/t | C10: 50 | D10: 50 | E10: Harga DMO dibatasi (cap USD 70/t @6.322 GAR), disesuaikan CV
A11: ASP – Domestik non-DMO (industri) | B11: USD/t | C11: 65 | D11: 58
A12: Nilai kalori rata-rata produk | B12: kcal/kg GAR | C12: 4600 | D12: 4600
A13: 2. VOLUME OPERASI
A14: Produksi batubara (ROM) | B14: ton | C14: 10800000 | D14: 11800000
A15: Stripping ratio (SR) | B15: bcm/ton | C15: 7.8 | D15: 7.4 | E15: Sesuai rencana tambang (RKAB)
A16: Pengupasan tanah penutup (OB removal) | B16: bcm | C16: =C14*C15 | D16: =D14*D15
A17: Jarak hauling tambang – pelabuhan | B17: km | C17: 42 | D17: 42
A18: Penjualan – Ekspor | B18: ton | C18: 6900000 | D18: 7600000
A19: Penjualan – Domestik DMO | B19: ton | C19: 2700000 | D19: 2900000
A20: Penjualan – Domestik non-DMO | B20: ton | C20: 1100000 | D20: 1150000
A21: Total penjualan | B21: ton | C21: =SUM(C18:C20) | D21: =SUM(D18:D20)
A22: Porsi DMO terhadap total penjualan | B22: % | C22: =IFERROR(C19/C21,0) | D22: =IFERROR(D19/D21,0) | E22: Kewajiban DMO minimal 25% (Kepmen ESDM)
A23: Stok batubara awal tahun | B23: ton | C23: 450000 | D23: =C24 | E23: 2025 = stok akhir 2024
A24: Stok batubara akhir tahun | B24: ton | C24: =C23+C14-C21 | D24: =D23+D14-D21
A25: Jumlah karyawan organik | B25: orang | C25: 1150 | D25: 1180
A26: 3. TARIF BIAYA TAMBANG & LOGISTIK
A27: Tarif kontraktor OB (excl. BBM) | B27: USD/bcm | C27: 1.85 | D27: 1.8 | E27: BBM disuplai pemilik (owner-supplied fuel)
A28: Tarif coal getting | B28: USD/ton | C28: 0.95 | D28: 0.95
A29: Rasio BBM (fuel ratio) | B29: liter/bcm | C29: 0.95 | D29: 0.9
A30: Harga BBM solar industri | B30: Rp/liter | C30: 13500 | D30: 13000
A31: Porsi OB yang diledakkan | B31: % | C31: 0.4 | D31: 0.4
A32: Tarif drill & blast | B32: USD/bcm | C32: 0.45 | D32: 0.45
A33: Tarif crushing & pengolahan (CPP) | B33: USD/ton | C33: 0.85 | D33: 0.82
A34: Tarif hauling | B34: USD/ton-km | C34: 0.105 | D34: 0.1
A35: Tarif pelabuhan & stockpile | B35: USD/ton | C35: 1.25 | D35: 1.2 | E35: Basis ton penjualan
A36: Tarif tongkang & transshipment | B36: USD/ton | C36: 4.1 | D36: 3.95 | E36: Basis ton penjualan
A37: Tarif royalti efektif (PNBP) | B37: % pendapatan | C37: 0.07 | D37: 0.065 | E37: IUP: bertingkat per CV & HBA (PP 26/2022); IUPK: PP 15/2022
A38: Penyesuaian harga / penalti kualitas | B38: % pendapatan | C38: 0.006 | D38: 0.005 | E38: Penalti CV, TM, ash, sulfur
A39: 4. BIAYA TETAP TAMBANG & OVERHEAD SITE (Rp juta)
A40: Sewa alat berat & sarana penunjang | B40: Rp juta | C40: 120000 | D40: 115000
A41: Pemeliharaan jalan tambang & infrastruktur | B41: Rp juta | C41: 65000 | D41: 68000
A42: Pengelolaan air tambang (dewatering) | B42: Rp juta | C42: 48000 | D42: 52000
...

Sheet A2 Laba Rugi Contoh
A1: PT Batubara Contoh Tbk (fiktif) – Laporan Laba Rugi Konsolidasian
A2: Untuk tahun yang berakhir 31 Desember | dalam Rp juta | angka ilustratif, bukan data emiten sebenarnya
A5: Uraian | B5: Basis perhitungan | C5: FY2024 | D5: FY2025 | E5: Δ% YoY | F5: % thd pendapatan FY2025
A6: PENDAPATAN
A7: Penjualan batubara – Ekspor | B7: Vol × ASP × kurs | C7: ='A1 Asumsi Contoh'!C18*'A1 Asumsi Contoh'!C9*'A1 Asumsi Contoh'!C7/1000000 | D7: ='A1 Asumsi Contoh'!D18*'A1 Asumsi Contoh'!D9*'A1 Asumsi Contoh'!D7/1000000 | E7: =IFERROR((D7-C7)/ABS(C7),"") | F7: =IFERROR(D7/D$13,"")
A8: Penjualan batubara – Domestik DMO | B8: Vol × ASP × kurs | C8: ='A1 Asumsi Contoh'!C19*'A1 Asumsi Contoh'!C10*'A1 Asumsi Contoh'!C7/1000000 | D8: ='A1 Asumsi Contoh'!D19*'A1 Asumsi Contoh'!D10*'A1 Asumsi Contoh'!D7/1000000 | E8: =IFERROR((D8-C8)/ABS(C8),"") | F8: =IFERROR(D8/D$13,"")
A9: Penjualan batubara – Domestik non-DMO | B9: Vol × ASP × kurs | C9: ='A1 Asumsi Contoh'!C20*'A1 Asumsi Contoh'!C11*'A1 Asumsi Contoh'!C7/1000000 | D9: ='A1 Asumsi Contoh'!D20*'A1 Asumsi Contoh'!D11*'A1 Asumsi Contoh'!D7/1000000 | E9: =IFERROR((D9-C9)/ABS(C9),"") | F9: =IFERROR(D9/D$13,"")
A10: Subtotal penjualan batubara | C10: =SUM(C7:C9) | D10: =SUM(D7:D9) | E10: =IFERROR((D10-C10)/ABS(C10),"") | F10: =IFERROR(D10/D$13,"")
A11: Penyesuaian harga / penalti kualitas | B11: % × penjualan | C11: =-C10*'A1 Asumsi Contoh'!C38 | D11: =-D10*'A1 Asumsi Contoh'!D38 | E11: =IFERROR((D11-C11)/ABS(C11),"") | F11: =IFERROR(D11/D$13,"")
A12: Pendapatan jasa pelabuhan/hauling pihak ketiga | C12: ='A1 Asumsi Contoh'!C73 | D12: ='A1 Asumsi Contoh'!D73 | E12: =IFERROR((D12-C12)/ABS(C12),"") | F12: =IFERROR(D12/D$13,"")
A13: PENDAPATAN BERSIH | C13: =C10+C11+C12 | D13: =D10+D11+D12 | E13: =IFERROR((D13-C13)/ABS(C13),"") | F13: =IFERROR(D13/D$13,"")
A15: BEBAN POKOK PENDAPATAN
A16: A. Biaya penambangan
A17: Pengupasan OB – jasa kontraktor | B17: bcm × tarif × kurs | C17: ='A1 Asumsi Contoh'!C16*'A1 Asumsi Contoh'!C27*'A1 Asumsi Contoh'!C7/1000000 | D17: ='A1 Asumsi Contoh'!D16*'A1 Asumsi Contoh'!D27*'A1 Asumsi Contoh'!D7/1000000 | E17: =IFERROR((D17-C17)/ABS(C17),"") | F17: =IFERROR(D17/D$13,"")
A18: Bahan bakar (BBM) | B18: bcm × L/bcm × Rp/L | C18: ='A1 Asumsi Contoh'!C16*'A1 Asumsi Contoh'!C29*'A1 Asumsi Contoh'!C30/1000000 | D18: ='A1 Asumsi Contoh'!D16*'A1 Asumsi Contoh'!D29*'A1 Asumsi Contoh'!D30/1000000 | E18: =IFERROR((D18-C18)/ABS(C18),"") | F18: =IFERROR(D18/D$13,"")
A19: Peledakan (drill & blast) | B19: bcm × % × tarif | C19: ='A1 Asumsi Contoh'!C16*'A1 Asumsi Contoh'!C31*'A1 Asumsi Contoh'!C32*'A1 Asumsi Contoh'!C7/1000000 | D19: ='A1 Asumsi Contoh'!D16*'A1 Asumsi Contoh'!D31*'A1 Asumsi Contoh'!D32*'A1 Asumsi Contoh'!D7/1000000 | E19: =IFERROR((D19-C19)/ABS(C19),"") | F19: =IFERROR(D19/D$13,"")
A20: Penggalian batubara (coal getting) | B20: ton × tarif | C20: ='A1 Asumsi Contoh'!C14*'A1 Asumsi Contoh'!C28*'A1 Asumsi Contoh'!C7/1000000 | D20: ='A1 Asumsi Contoh'!D14*'A1 Asumsi Contoh'!D28*'A1 Asumsi Contoh'!D7/1000000 | E20: =IFERROR((D20-C20)/ABS(C20),"") | F20: =IFERROR(D20/D$13,"")
A21: Sewa alat berat & sarana penunjang | C21: ='A1 Asumsi Contoh'!C40 | D21: ='A1 Asumsi Contoh'!D40 | E21: =IFERROR((D21-C21)/ABS(C21),"") | F21: =IFERROR(D21/D$13,"")
A22: Pemeliharaan jalan tambang & infrastruktur | C22: ='A1 Asumsi Contoh'!C41 | D22: ='A1 Asumsi Contoh'!D41 | E22: =IFERROR((D22-C22)/ABS(C22),"") | F22: =IFERROR(D22/D$13,"")
A23: Pengelolaan air tambang (dewatering) | C23: ='A1 Asumsi Contoh'!C42 | D23: ='A1 Asumsi Contoh'!D42 | E23: =IFERROR((D23-C23)/ABS(C23),"") | F23: =IFERROR(D23/D$13,"")
A24: Survei, geologi & grade control | C24: ='A1 Asumsi Contoh'!C43 | D24: ='A1 Asumsi Contoh'!D43 | E24: =IFERROR((D24-C24)/ABS(C24),"") | F24: =IFERROR(D24/D$13,"")
A25: Subtotal biaya penambangan | C25: =SUM(C17:C24) | D25: =SUM(D17:D24) | E25: =IFERROR((D25-C25)/ABS(C25),"") | F25: =IFERROR(D25/D$13,"")
A26: B. Pengolahan & logistik
A27: Crushing & pengolahan (CPP) | B27: ton produksi × tarif | C27: ='A1 Asumsi Contoh'!C14*'A1 Asumsi Contoh'!C33*'A1 Asumsi Contoh'!C7/1000000 | D27: ='A1 Asumsi Contoh'!D14*'A1 Asumsi Contoh'!D33*'A1 Asumsi Contoh'!D7/1000000 | E27: =IFERROR((D27-C27)/ABS(C27),"") | F27: =IFERROR(D27/D$13,"")
A28: Hauling tambang – pelabuhan | B28: ton × km × tarif | C28: ='A1 Asumsi Contoh'!C14*'A1 Asumsi Contoh'!C17*'A1 Asumsi Contoh'!C34*'A1 Asumsi Contoh'!C7/1000000 | D28: ='A1 Asumsi Contoh'!D14*'A1 Asumsi Contoh'!D17*'A1 Asumsi Contoh'!D34*'A1 Asumsi Contoh'!D7/1000000 | E28: =IFERROR((D28-C28)/ABS(C28),"") | F28: =IFERROR(D28/D$13,"")
A29: Penanganan pelabuhan & stockpile | B29: ton jual × tarif | C29: ='A1 Asumsi Contoh'!C21*'A1 Asumsi Contoh'!C35*'A1 Asumsi Contoh'!C7/1000000 | D29: ='A1 Asumsi Contoh'!D21*'A1 Asumsi Contoh'!D35*'A1 Asumsi Contoh'!D7/1000000 | E29: =IFERROR((D29-C29)/ABS(C29),"") | F29: =IFERROR(D29/D$13,"")
A30: Tongkang & transshipment (barging) | B30: ton jual × tarif | C30: ='A1 Asumsi Contoh'!C21*'A1 Asumsi Contoh'!C36*'A1 Asumsi Contoh'!C7/1000000 | D30: ='A1 Asumsi Contoh'!D21*'A1 Asumsi Contoh'!D36*'A1 Asumsi Contoh'!D7/1000000 | E30: =IFERROR((D30-C30)/ABS(C30),"") | F30: =IFERROR(D30/D$13,"")
A31: Subtotal pengolahan & logistik | C31: =SUM(C27:C30) | D31: =SUM(D27:D30) | E31: =IFERROR((D31-C31)/ABS(C31),"") | F31: =IFERROR(D31/D$13,"")
A32: C. Royalti
A33: Royalti / PNBP (DHPB) | B33: penjualan neto × tarif | C33: =(C10+C11)*'A1 Asumsi Contoh'!C37 | D33: =(D10+D11)*'A1 Asumsi Contoh'!D37 | E33: =IFERROR((D33-C33)/ABS(C33),"") | F33: =IFERROR(D33/D$13,"")
A34: D. Biaya tidak langsung tambang (site overhead)
A35: Gaji & tunjangan karyawan site | C35: ='A1 Asumsi Contoh'!C44 | D35: ='A1 Asumsi Contoh'!D44 | E35: =IFERROR((D35-C35)/ABS(C35),"") | F35: =IFERROR(D35/D$13,"")
A36: Camp, mess & katering | C36: ='A1 Asumsi Contoh'!C45 | D36: ='A1 Asumsi Contoh'!D45 | E36: =IFERROR((D36-C36)/ABS(C36),"") | F36: =IFERROR(D36/D$13,"")
A37: K3 / HSE | C37: ='A1 Asumsi Contoh'!C46 | D37: ='A1 Asumsi Contoh'!D46 | E37: =IFERROR((D37-C37)/ABS(C37),"") | F37: =IFERROR(D37/D$13,"")
A38: Lingkungan & reklamasi (provisi) | C38: ='A1 Asumsi Contoh'!C47 | D38: ='A1 Asumsi Contoh'!D47 | E38: =IFERROR((D38-C38)/ABS(C38),"") | F38: =IFERROR(D38/D$13,"")
A39: PPM / CSR | C39: ='A1 Asumsi Contoh'!C48 | D39: ='A1 Asumsi Contoh'!D48 | E39: =IFERROR((D39-C39)/ABS(C39),"") | F39: =IFERROR(D39/D$13,"")
A40: Iuran tetap & kompensasi lahan | C40: ='A1 Asumsi Contoh'!C49 | D40: ='A1 Asumsi Contoh'!D49 | E40: =IFERROR((D40-C40)/ABS(C40),"") | F40: =IFERROR(D40/D$13,"")
A41: Subtotal overhead site | C41: =SUM(C35:C40) | D41: =SUM(D35:D40) | E41: =IFERROR((D41-C41)/ABS(C41),"") | F41: =IFERROR(D41/D$13,"")
A42: E. Penyusutan & amortisasi
A43: Penyusutan aset tetap | C43: ='A1 Asumsi Contoh'!C51 | D43: ='A1 Asumsi Contoh'!D51 | E43: =IFERROR((D43-C43)/ABS(C43),"") | F43: =IFERROR(D43/D$13,"")
...

Sheet A3 Neraca Contoh
A1: PT Batubara Contoh Tbk (fiktif) – Laporan Posisi Keuangan (Neraca) Konsolidasian
A2: Per 31 Desember | dalam Rp juta | kolom 2023 = saldo awal (input); 2024–2025 dihitung dari driver & arus kas
A5: Uraian | B5: Basis | C5: 31 Des 2023 | D5: 31 Des 2024 | E5: 31 Des 2025
A6: ASET
A7: Aset lancar
A8: Kas dan setara kas | C8: 1450000 | D8: ='A4 Arus Kas Contoh'!C46 | E8: ='A4 Arus Kas Contoh'!D46
A9: Piutang usaha | B9: DSO | C9: 850000 | D9: ='A2 Laba Rugi Contoh'!C13*'A1 Asumsi Contoh'!C95/365 | E9: ='A2 Laba Rugi Contoh'!D13*'A1 Asumsi Contoh'!D95/365
A10: Piutang lain-lain | C10: 55000 | D10: ='A1 Asumsi Contoh'!C98 | E10: ='A1 Asumsi Contoh'!D98
A11: Persediaan batubara | B11: stok × biaya/ton | C11: 243000 | D11: ='A1 Asumsi Contoh'!C24*'A2 Laba Rugi Contoh'!C95/1000000 | E11: ='A1 Asumsi Contoh'!D24*'A2 Laba Rugi Contoh'!D95/1000000
A12: Persediaan suku cadang & BBM | C12: 195000 | D12: ='A1 Asumsi Contoh'!C97 | E12: ='A1 Asumsi Contoh'!D97
A13: Uang muka & biaya dibayar dimuka | C13: 90000 | D13: ='A1 Asumsi Contoh'!C99 | E13: ='A1 Asumsi Contoh'!D99
A14: Pajak dibayar dimuka | C14: 130000 | D14: ='A1 Asumsi Contoh'!C100 | E14: ='A1 Asumsi Contoh'!D100
A15: Jumlah aset lancar | C15: =SUM(C8:C14) | D15: =SUM(D8:D14) | E15: =SUM(E8:E14)
A16: Aset tidak lancar
A17: Aset tetap – neto (termasuk aset hak guna) | C17: 2650000 | D17: =C17+'A1 Asumsi Contoh'!C90-'A1 Asumsi Contoh'!C51-'A1 Asumsi Contoh'!C54 | E17: =D17+'A1 Asumsi Contoh'!D90-'A1 Asumsi Contoh'!D51-'A1 Asumsi Contoh'!D54
A18: Properti pertambangan – neto | C18: 1450000 | D18: =C18+'A1 Asumsi Contoh'!C91-'A1 Asumsi Contoh'!C52 | E18: =D18+'A1 Asumsi Contoh'!D91-'A1 Asumsi Contoh'!D52
A19: Aset eksplorasi & evaluasi | C19: 80000 | D19: =C19+'A1 Asumsi Contoh'!C93 | E19: =D19+'A1 Asumsi Contoh'!D93
A20: Biaya pengupasan tangguhan – neto | C20: 420000 | D20: =C20+'A1 Asumsi Contoh'!C92-'A1 Asumsi Contoh'!C53 | E20: =D20+'A1 Asumsi Contoh'!D92-'A1 Asumsi Contoh'!D53
A21: Investasi pada entitas asosiasi | C21: 180000 | D21: =C21+'A2 Laba Rugi Contoh'!C83 | E21: =D21+'A2 Laba Rugi Contoh'!D83
A22: Dana jaminan reklamasi (dibatasi) | C22: 110000 | D22: ='A1 Asumsi Contoh'!C106 | E22: ='A1 Asumsi Contoh'!D106
A23: Aset pajak tangguhan | C23: 55000 | D23: =C23 | E23: =D23
A24: Aset tidak lancar lainnya | C24: 38000 | D24: ='A1 Asumsi Contoh'!C107 | E24: ='A1 Asumsi Contoh'!D107
A25: Jumlah aset tidak lancar | C25: =SUM(C17:C24) | D25: =SUM(D17:D24) | E25: =SUM(E17:E24)
A26: JUMLAH ASET | C26: =C15+C25 | D26: =D15+D25 | E26: =E15+E25
A28: LIABILITAS
A29: Liabilitas jangka pendek
A30: Utang usaha (kontraktor & pemasok) | B30: DPO | C30: 620000 | D30: =('A2 Laba Rugi Contoh'!C25+'A2 Laba Rugi Contoh'!C31+'A2 Laba Rugi Contoh'!C41-'A2 Laba Rugi Contoh'!C38)*'A1 Asumsi Contoh'!C96/365 | E30: =('A2 Laba Rugi Contoh'!D25+'A2 Laba Rugi Contoh'!D31+'A2 Laba Rugi Contoh'!D41-'A2 Laba Rugi Contoh'!D38)*'A1 Asumsi Contoh'!D96/365
A31: Utang royalti | C31: 70000 | D31: ='A2 Laba Rugi Contoh'!C33/12*'A1 Asumsi Contoh'!C102 | E31: ='A2 Laba Rugi Contoh'!D33/12*'A1 Asumsi Contoh'!D102
A32: Beban akrual | C32: 140000 | D32: ='A1 Asumsi Contoh'!C101 | E32: ='A1 Asumsi Contoh'!D101
A33: Utang pajak | C33: 150000 | D33: ='A2 Laba Rugi Contoh'!C88*'A1 Asumsi Contoh'!C103 | E33: ='A2 Laba Rugi Contoh'!D88*'A1 Asumsi Contoh'!D103
A34: Pinjaman bank jangka pendek | C34: 100000 | D34: ='A1 Asumsi Contoh'!C83 | E34: ='A1 Asumsi Contoh'!D83
A35: Bagian lancar pinjaman bank jangka panjang | C35: 350000 | D35: ='A1 Asumsi Contoh'!C81 | E35: ='A1 Asumsi Contoh'!D81
A36: Jumlah liabilitas jangka pendek | C36: =SUM(C30:C35) | D36: =SUM(D30:D35) | E36: =SUM(E30:E35)
A37: Liabilitas jangka panjang
A38: Pinjaman bank jangka panjang – setelah bagian lancar | C38: 1550000 | D38: ='A1 Asumsi Contoh'!C82-D35 | E38: ='A1 Asumsi Contoh'!D82-E35
A39: Provisi reklamasi & penutupan tambang | C39: 380000 | D39: =C39+'A2 Laba Rugi Contoh'!C38-'A1 Asumsi Contoh'!C104 | E39: =D39+'A2 Laba Rugi Contoh'!D38-'A1 Asumsi Contoh'!D104
A40: Liabilitas imbalan kerja | C40: 170000 | D40: ='A1 Asumsi Contoh'!C105 | E40: ='A1 Asumsi Contoh'!D105
A41: Liabilitas pajak tangguhan | C41: 120000 | D41: =C41 | E41: =D41
A42: Jumlah liabilitas jangka panjang | C42: =SUM(C38:C41) | D42: =SUM(D38:D41) | E42: =SUM(E38:E41)
A43: JUMLAH LIABILITAS | C43: =C36+C42 | D43: =D36+D42 | E43: =E36+E42
...

Sheet A4 Arus Kas Contoh
A1: PT Batubara Contoh Tbk (fiktif) – Laporan Arus Kas Konsolidasian
A2: Untuk tahun yang berakhir 31 Desember | dalam Rp juta | metode tidak langsung + rekonsiliasi metode langsung
A5: Uraian | B5: Basis | C5: FY2024 | D5: FY2025
A6: ARUS KAS DARI AKTIVITAS OPERASI (metode tidak langsung)
A7: Laba bersih tahun berjalan | C7: ='A2 Laba Rugi Contoh'!C89 | D7: ='A2 Laba Rugi Contoh'!D89
A8: Penyesuaian pos non-kas
A9: Penyusutan & amortisasi | C9: ='A2 Laba Rugi Contoh'!C46+'A2 Laba Rugi Contoh'!C71 | D9: ='A2 Laba Rugi Contoh'!D46+'A2 Laba Rugi Contoh'!D71
A10: Bagian laba entitas asosiasi | C10: =-'A2 Laba Rugi Contoh'!C83 | D10: =-'A2 Laba Rugi Contoh'!D83
A11: Kenaikan provisi reklamasi – neto | C11: =('A3 Neraca Contoh'!D39-'A3 Neraca Contoh'!C39) | D11: =('A3 Neraca Contoh'!E39-'A3 Neraca Contoh'!D39)
A12: Kenaikan liabilitas imbalan kerja | C12: =('A3 Neraca Contoh'!D40-'A3 Neraca Contoh'!C40) | D12: =('A3 Neraca Contoh'!E40-'A3 Neraca Contoh'!D40)
A13: Perubahan pajak tangguhan | C13: =-('A3 Neraca Contoh'!D23-'A3 Neraca Contoh'!C23)+('A3 Neraca Contoh'!D41-'A3 Neraca Contoh'!C41) | D13: =-('A3 Neraca Contoh'!E23-'A3 Neraca Contoh'!D23)+('A3 Neraca Contoh'!E41-'A3 Neraca Contoh'!D41)
A14: Perubahan modal kerja
A15: Piutang usaha | C15: =-('A3 Neraca Contoh'!D9-'A3 Neraca Contoh'!C9) | D15: =-('A3 Neraca Contoh'!E9-'A3 Neraca Contoh'!D9)
A16: Piutang lain-lain | C16: =-('A3 Neraca Contoh'!D10-'A3 Neraca Contoh'!C10) | D16: =-('A3 Neraca Contoh'!E10-'A3 Neraca Contoh'!D10)
A17: Persediaan batubara | C17: =-('A3 Neraca Contoh'!D11-'A3 Neraca Contoh'!C11) | D17: =-('A3 Neraca Contoh'!E11-'A3 Neraca Contoh'!D11)
A18: Persediaan suku cadang & BBM | C18: =-('A3 Neraca Contoh'!D12-'A3 Neraca Contoh'!C12) | D18: =-('A3 Neraca Contoh'!E12-'A3 Neraca Contoh'!D12)
A19: Uang muka & biaya dibayar dimuka | C19: =-('A3 Neraca Contoh'!D13-'A3 Neraca Contoh'!C13) | D19: =-('A3 Neraca Contoh'!E13-'A3 Neraca Contoh'!D13)
A20: Pajak dibayar dimuka | C20: =-('A3 Neraca Contoh'!D14-'A3 Neraca Contoh'!C14) | D20: =-('A3 Neraca Contoh'!E14-'A3 Neraca Contoh'!D14)
A21: Utang usaha | C21: =('A3 Neraca Contoh'!D30-'A3 Neraca Contoh'!C30) | D21: =('A3 Neraca Contoh'!E30-'A3 Neraca Contoh'!D30)
A22: Utang royalti | C22: =('A3 Neraca Contoh'!D31-'A3 Neraca Contoh'!C31) | D22: =('A3 Neraca Contoh'!E31-'A3 Neraca Contoh'!D31)
A23: Beban akrual | C23: =('A3 Neraca Contoh'!D32-'A3 Neraca Contoh'!C32) | D23: =('A3 Neraca Contoh'!E32-'A3 Neraca Contoh'!D32)
A24: Utang pajak | C24: =('A3 Neraca Contoh'!D33-'A3 Neraca Contoh'!C33) | D24: =('A3 Neraca Contoh'!E33-'A3 Neraca Contoh'!D33)
A25: Kas bersih dari aktivitas operasi | C25: =SUM(C7:C24) | D25: =SUM(D7:D24)
A27: ARUS KAS DARI AKTIVITAS INVESTASI
A28: Perolehan aset tetap | C28: =-(('A3 Neraca Contoh'!D17-'A3 Neraca Contoh'!C17)+'A2 Laba Rugi Contoh'!C43+'A2 Laba Rugi Contoh'!C71) | D28: =-(('A3 Neraca Contoh'!E17-'A3 Neraca Contoh'!D17)+'A2 Laba Rugi Contoh'!D43+'A2 Laba Rugi Contoh'!D71)
A29: Penambahan properti pertambangan | C29: =-(('A3 Neraca Contoh'!D18-'A3 Neraca Contoh'!C18)+'A2 Laba Rugi Contoh'!C44) | D29: =-(('A3 Neraca Contoh'!E18-'A3 Neraca Contoh'!D18)+'A2 Laba Rugi Contoh'!D44)
A30: Biaya pengupasan tangguhan | C30: =-(('A3 Neraca Contoh'!D20-'A3 Neraca Contoh'!C20)+'A2 Laba Rugi Contoh'!C45) | D30: =-(('A3 Neraca Contoh'!E20-'A3 Neraca Contoh'!D20)+'A2 Laba Rugi Contoh'!D45)
A31: Pengeluaran eksplorasi & evaluasi | C31: =-('A3 Neraca Contoh'!D19-'A3 Neraca Contoh'!C19) | D31: =-('A3 Neraca Contoh'!E19-'A3 Neraca Contoh'!D19)
A32: Penempatan dana jaminan reklamasi | C32: =-('A3 Neraca Contoh'!D22-'A3 Neraca Contoh'!C22) | D32: =-('A3 Neraca Contoh'!E22-'A3 Neraca Contoh'!D22)
A33: Aset tidak lancar lainnya | C33: =-('A3 Neraca Contoh'!D24-'A3 Neraca Contoh'!C24) | D33: =-('A3 Neraca Contoh'!E24-'A3 Neraca Contoh'!D24)
A34: Kas bersih untuk aktivitas investasi | C34: =SUM(C28:C33) | D34: =SUM(D28:D33)
A36: ARUS KAS DARI AKTIVITAS PENDANAAN
A37: Penerimaan (pembayaran) pinjaman jangka pendek – neto | C37: =('A3 Neraca Contoh'!D34-'A3 Neraca Contoh'!C34) | D37: =('A3 Neraca Contoh'!E34-'A3 Neraca Contoh'!D34)
A38: Penerimaan pinjaman bank jangka panjang | C38: ='A1 Asumsi Contoh'!C79 | D38: ='A1 Asumsi Contoh'!D79
A39: Pembayaran pinjaman bank jangka panjang | C39: =-'A1 Asumsi Contoh'!C80 | D39: =-'A1 Asumsi Contoh'!D80
A40: Pembayaran dividen | C40: =-'A1 Asumsi Contoh'!C88 | D40: =-'A1 Asumsi Contoh'!D88
A41: Perubahan ekuitas lainnya | C41: =('A3 Neraca Contoh'!D46-'A3 Neraca Contoh'!C46)+('A3 Neraca Contoh'!D47-'A3 Neraca Contoh'!C47)+('A3 Neraca Contoh'!D49-'A3 Neraca Contoh'!C49)+('A3 Neraca Contoh'!D50-'A3 Neraca Contoh'!C50) | D41: =('A3 Neraca Contoh'!E46-'A3 Neraca Contoh'!D46)+('A3 Neraca Contoh'!E47-'A3 Neraca Contoh'!D47)+('A3 Neraca Contoh'!E49-'A3 Neraca Contoh'!D49)+('A3 Neraca Contoh'!E50-'A3 Neraca Contoh'!D50)
A42: Kas bersih dari (untuk) aktivitas pendanaan | C42: =SUM(C37:C41) | D42: =SUM(D37:D41)
A44: KENAIKAN (PENURUNAN) BERSIH KAS | C44: =C25+C34+C42 | D44: =D25+D34+D42
A45: Kas dan setara kas awal tahun | C45: ='A3 Neraca Contoh'!C8 | D45: ='A3 Neraca Contoh'!D8
...

Sheet B1 Struktur Rev-Cost
A1: Struktur Pendapatan & Struktur Biaya – Perusahaan Tambang Batubara (model contoh)
A2: Sumber angka: sheet A1–A2. Dalam Rp juta kecuali disebutkan.
A4: 1. STRUKTUR PENDAPATAN (REVENUE STRUCTURE)
A5: Segmen pendapatan | B5: Volume 2024 (ton) | C5: ASP 2024 (USD/t) | D5: Pendapatan 2024 | E5: Porsi 2024 | F5: Volume 2025 (ton) | G5: ASP 2025 (USD/t) | H5: Pendapatan 2025 | I5: Porsi 2025 | J5: Pertumbuhan
A6: Ekspor | B6: ='A1 Asumsi Contoh'!C18 | C6: ='A1 Asumsi Contoh'!C9 | D6: ='A2 Laba Rugi Contoh'!C7 | E6: =IFERROR(D6/D$11,0) | F6: ='A1 Asumsi Contoh'!D18 | G6: ='A1 Asumsi Contoh'!D9 | H6: ='A2 Laba Rugi Contoh'!D7 | I6: =IFERROR(H6/H$11,0) | J6: =IFERROR((H6-D6)/ABS(D6),"")
A7: Domestik – DMO (kelistrikan) | B7: ='A1 Asumsi Contoh'!C19 | C7: ='A1 Asumsi Contoh'!C10 | D7: ='A2 Laba Rugi Contoh'!C8 | E7: =IFERROR(D7/D$11,0) | F7: ='A1 Asumsi Contoh'!D19 | G7: ='A1 Asumsi Contoh'!D10 | H7: ='A2 Laba Rugi Contoh'!D8 | I7: =IFERROR(H7/H$11,0) | J7: =IFERROR((H7-D7)/ABS(D7),"")
A8: Domestik – non-DMO (industri) | B8: ='A1 Asumsi Contoh'!C20 | C8: ='A1 Asumsi Contoh'!C11 | D8: ='A2 Laba Rugi Contoh'!C9 | E8: =IFERROR(D8/D$11,0) | F8: ='A1 Asumsi Contoh'!D20 | G8: ='A1 Asumsi Contoh'!D11 | H8: ='A2 Laba Rugi Contoh'!D9 | I8: =IFERROR(H8/H$11,0) | J8: =IFERROR((H8-D8)/ABS(D8),"")
A9: Penyesuaian harga / penalti kualitas | D9: ='A2 Laba Rugi Contoh'!C11 | E9: =IFERROR(D9/D$11,0) | H9: ='A2 Laba Rugi Contoh'!D11 | I9: =IFERROR(H9/H$11,0) | J9: =IFERROR((H9-D9)/ABS(D9),"")
A10: Pendapatan jasa pihak ketiga | D10: ='A2 Laba Rugi Contoh'!C12 | E10: =IFERROR(D10/D$11,0) | H10: ='A2 Laba Rugi Contoh'!D12 | I10: =IFERROR(H10/H$11,0) | J10: =IFERROR((H10-D10)/ABS(D10),"")
A11: TOTAL PENDAPATAN BERSIH | B11: =SUM(B6:B10) | C11: =IFERROR(SUM(D6:D8)*1000000/B11/'A1 Asumsi Contoh'!C7,0) | D11: =SUM(D6:D10) | E11: =SUM(E6:E10) | F11: =SUM(F6:F10) | G11: =IFERROR(SUM(H6:H8)*1000000/F11/'A1 Asumsi Contoh'!D7,0) | H11: =SUM(H6:H10) | I11: =SUM(I6:I10) | J11: =IFERROR((H11-D11)/ABS(D11),"")
A12: ASP total = ASP rata-rata tertimbang penjualan batubara (excl. penalti & jasa).
A13: Pemicu pendapatan: Pendapatan batubara = Volume penjualan (ton) × Harga realisasi (USD/t) × Kurs (Rp/USD) ± penyesuaian kualitas.
A14: Harga realisasi dipengaruhi: indeks acuan (HBA / ICI / Newcastle), nilai kalori (GAR/NAR), spesifikasi (TM, ash, sulfur), term FOB vs CIF, dan kontrak DMO (cap harga).
A15: Bauran pasar: ekspor (harga pasar, eksposur USD), DMO (harga dibatasi, kewajiban ≥25%), domestik non-DMO (industri/semen/smelter). Pendapatan jasa = pemanfaatan pelabuhan/jalan hauling oleh pihak ketiga.
A18: 2. STRUKTUR BIAYA (COST STRUCTURE) – total biaya = BPP + beban usaha + beban keuangan
A19: Komponen biaya | B19: FY2024 (Rp juta) | C19: FY2025 (Rp juta) | D19: Porsi thd total biaya 2025 | E19: % thd pendapatan 2025 | F19: USD/t terjual 2025 | G19: Sifat biaya | H19: Pemicu biaya (cost driver) | I19: Dapat dikendalikan | J19: Δ% YoY
A20: Pengupasan OB (kontraktor + BBM + peledakan) | B20: ='A2 Laba Rugi Contoh'!C17+'A2 Laba Rugi Contoh'!C18+'A2 Laba Rugi Contoh'!C19 | C20: ='A2 Laba Rugi Contoh'!D17+'A2 Laba Rugi Contoh'!D18+'A2 Laba Rugi Contoh'!D19 | D20: =IFERROR(C20/C$35,0) | E20: =IFERROR(C20/'A2 Laba Rugi Contoh'!D13,0) | F20: =IFERROR(C20*1000000/'A1 Asumsi Contoh'!D21/'A1 Asumsi Contoh'!D7,0) | G20: Variabel | H20: Volume OB (bcm) = produksi × SR; tarif; harga BBM | I20: Ya | J20: =IFERROR((C20-B20)/ABS(B20),"")
A21: Penggalian batubara (coal getting) | B21: ='A2 Laba Rugi Contoh'!C20 | C21: ='A2 Laba Rugi Contoh'!D20 | D21: =IFERROR(C21/C$35,0) | E21: =IFERROR(C21/'A2 Laba Rugi Contoh'!D13,0) | F21: =IFERROR(C21*1000000/'A1 Asumsi Contoh'!D21/'A1 Asumsi Contoh'!D7,0) | G21: Variabel | H21: Ton produksi × tarif | I21: Ya | J21: =IFERROR((C21-B21)/ABS(B21),"")
A22: Biaya tambang tetap (sewa alat, pemeliharaan, dewatering, survei) | B22: ='A2 Laba Rugi Contoh'!C21+'A2 Laba Rugi Contoh'!C22+'A2 Laba Rugi Contoh'!C23+'A2 Laba Rugi Contoh'!C24 | C22: ='A2 Laba Rugi Contoh'!D21+'A2 Laba Rugi Contoh'!D22+'A2 Laba Rugi Contoh'!D23+'A2 Laba Rugi Contoh'!D24 | D22: =IFERROR(C22/C$35,0) | E22: =IFERROR(C22/'A2 Laba Rugi Contoh'!D13,0) | F22: =IFERROR(C22*1000000/'A1 Asumsi Contoh'!D21/'A1 Asumsi Contoh'!D7,0) | G22: Tetap | H22: Kontrak periodik, curah hujan | I22: Ya | J22: =IFERROR((C22-B22)/ABS(B22),"")
A23: Crushing & pengolahan (CPP) | B23: ='A2 Laba Rugi Contoh'!C27 | C23: ='A2 Laba Rugi Contoh'!D27 | D23: =IFERROR(C23/C$35,0) | E23: =IFERROR(C23/'A2 Laba Rugi Contoh'!D13,0) | F23: =IFERROR(C23*1000000/'A1 Asumsi Contoh'!D21/'A1 Asumsi Contoh'!D7,0) | G23: Variabel | H23: Ton produksi | I23: Ya | J23: =IFERROR((C23-B23)/ABS(B23),"")
A24: Hauling tambang – pelabuhan | B24: ='A2 Laba Rugi Contoh'!C28 | C24: ='A2 Laba Rugi Contoh'!D28 | D24: =IFERROR(C24/C$35,0) | E24: =IFERROR(C24/'A2 Laba Rugi Contoh'!D13,0) | F24: =IFERROR(C24*1000000/'A1 Asumsi Contoh'!D21/'A1 Asumsi Contoh'!D7,0) | G24: Variabel | H24: Ton × jarak (km) × tarif | I24: Ya | J24: =IFERROR((C24-B24)/ABS(B24),"")
A25: Pelabuhan & stockpile | B25: ='A2 Laba Rugi Contoh'!C29 | C25: ='A2 Laba Rugi Contoh'!D29 | D25: =IFERROR(C25/C$35,0) | E25: =IFERROR(C25/'A2 Laba Rugi Contoh'!D13,0) | F25: =IFERROR(C25*1000000/'A1 Asumsi Contoh'!D21/'A1 Asumsi Contoh'!D7,0) | G25: Variabel | H25: Ton penjualan | I25: Ya | J25: =IFERROR((C25-B25)/ABS(B25),"")
A26: Tongkang & transshipment | B26: ='A2 Laba Rugi Contoh'!C30 | C26: ='A2 Laba Rugi Contoh'!D30 | D26: =IFERROR(C26/C$35,0) | E26: =IFERROR(C26/'A2 Laba Rugi Contoh'!D13,0) | F26: =IFERROR(C26*1000000/'A1 Asumsi Contoh'!D21/'A1 Asumsi Contoh'!D7,0) | G26: Variabel | H26: Ton penjualan; tarif pasar tongkang | I26: Sebagian | J26: =IFERROR((C26-B26)/ABS(B26),"")
A27: Royalti / PNBP | B27: ='A2 Laba Rugi Contoh'!C33 | C27: ='A2 Laba Rugi Contoh'!D33 | D27: =IFERROR(C27/C$35,0) | E27: =IFERROR(C27/'A2 Laba Rugi Contoh'!D13,0) | F27: =IFERROR(C27*1000000/'A1 Asumsi Contoh'!D21/'A1 Asumsi Contoh'!D7,0) | G27: Variabel | H27: Harga jual × tarif regulasi | I27: Tidak | J27: =IFERROR((C27-B27)/ABS(B27),"")
A28: Overhead site (gaji, camp, K3, PPM, lahan) | B28: ='A2 Laba Rugi Contoh'!C41-'A2 Laba Rugi Contoh'!C38 | C28: ='A2 Laba Rugi Contoh'!D41-'A2 Laba Rugi Contoh'!D38 | D28: =IFERROR(C28/C$35,0) | E28: =IFERROR(C28/'A2 Laba Rugi Contoh'!D13,0) | F28: =IFERROR(C28*1000000/'A1 Asumsi Contoh'!D21/'A1 Asumsi Contoh'!D7,0) | G28: Tetap | H28: Headcount & periode | I28: Ya | J28: =IFERROR((C28-B28)/ABS(B28),"")
A29: Lingkungan & reklamasi (provisi) | B29: ='A2 Laba Rugi Contoh'!C38 | C29: ='A2 Laba Rugi Contoh'!D38 | D29: =IFERROR(C29/C$35,0) | E29: =IFERROR(C29/'A2 Laba Rugi Contoh'!D13,0) | F29: =IFERROR(C29*1000000/'A1 Asumsi Contoh'!D21/'A1 Asumsi Contoh'!D7,0) | G29: Semi-variabel | H29: Luas bukaan lahan | I29: Sebagian | J29: =IFERROR((C29-B29)/ABS(B29),"")
A30: Penyusutan & amortisasi (BPP) | B30: ='A2 Laba Rugi Contoh'!C46 | C30: ='A2 Laba Rugi Contoh'!D46 | D30: =IFERROR(C30/C$35,0) | E30: =IFERROR(C30/'A2 Laba Rugi Contoh'!D13,0) | F30: =IFERROR(C30*1000000/'A1 Asumsi Contoh'!D21/'A1 Asumsi Contoh'!D7,0) | G30: Tetap | H30: Basis aset / unit produksi | I30: Tidak (jangka pendek) | J30: =IFERROR((C30-B30)/ABS(B30),"")
A31: Perubahan persediaan batubara | B31: ='A2 Laba Rugi Contoh'!C48 | C31: ='A2 Laba Rugi Contoh'!D48 | D31: =IFERROR(C31/C$35,0) | E31: =IFERROR(C31/'A2 Laba Rugi Contoh'!D13,0) | F31: =IFERROR(C31*1000000/'A1 Asumsi Contoh'!D21/'A1 Asumsi Contoh'!D7,0) | G31: Variabel | H31: Selisih produksi vs penjualan | I31: Sebagian | J31: =IFERROR((C31-B31)/ABS(B31),"")
A32: Beban penjualan | B32: ='A2 Laba Rugi Contoh'!C62 | C32: ='A2 Laba Rugi Contoh'!D62 | D32: =IFERROR(C32/C$35,0) | E32: =IFERROR(C32/'A2 Laba Rugi Contoh'!D13,0) | F32: =IFERROR(C32*1000000/'A1 Asumsi Contoh'!D21/'A1 Asumsi Contoh'!D7,0) | G32: Variabel | H32: Volume ekspor, demurrage, komisi | I32: Ya | J32: =IFERROR((C32-B32)/ABS(B32),"")
A33: Beban umum & administrasi | B33: ='A2 Laba Rugi Contoh'!C73 | C33: ='A2 Laba Rugi Contoh'!D73 | D33: =IFERROR(C33/C$35,0) | E33: =IFERROR(C33/'A2 Laba Rugi Contoh'!D13,0) | F33: =IFERROR(C33*1000000/'A1 Asumsi Contoh'!D21/'A1 Asumsi Contoh'!D7,0) | G33: Tetap | H33: Struktur organisasi kantor pusat | I33: Ya | J33: =IFERROR((C33-B33)/ABS(B33),"")
A34: Beban keuangan (bunga) | B34: =-'A2 Laba Rugi Contoh'!C81 | C34: =-'A2 Laba Rugi Contoh'!D81 | D34: =IFERROR(C34/C$35,0) | E34: =IFERROR(C34/'A2 Laba Rugi Contoh'!D13,0) | F34: =IFERROR(C34*1000000/'A1 Asumsi Contoh'!D21/'A1 Asumsi Contoh'!D7,0) | G34: Tetap | H34: Saldo pinjaman × suku bunga | I34: Sebagian | J34: =IFERROR((C34-B34)/ABS(B34),"")
A35: TOTAL BIAYA | B35: =SUM(B20:B34) | C35: =SUM(C20:C34) | D35: =SUM(D20:D34) | E35: =SUM(E20:E34) | F35: =SUM(F20:F34) | J35: =IFERROR((C35-B35)/ABS(B35),"")
A38: 3. BIAYA TETAP vs VARIABEL, MARJIN KONTRIBUSI & TITIK IMPAS (BREAKEVEN)
A39: Uraian | B39: FY2024 | C39: FY2025 | D39: Satuan | E39: Keterangan
A40: Porsi variabel dari biaya semi-variabel | B40: 0.5 | C40: =B40 | D40: % | E40: Asumsi: 50% biaya semi-variabel diperlakukan variabel
A41: Pendapatan bersih | B41: ='A2 Laba Rugi Contoh'!C13 | C41: ='A2 Laba Rugi Contoh'!D13 | D41: Rp juta
A42: Biaya variabel | B42: =SUMIF($G$20:$G$34,"Variabel",B$20:B$34)+B40*SUMIF($G$20:$G$34,"Semi-variabel",B$20:B$34) | C42: =SUMIF($G$20:$G$34,"Variabel",C$20:C$34)+C40*SUMIF($G$20:$G$34,"Semi-variabel",C$20:C$34) | D42: Rp juta | E42: Berubah proporsional dengan volume/harga
A43: Biaya tetap | B43: =SUMIF($G$20:$G$34,"Tetap",B$20:B$34)+(1-B40)*SUMIF($G$20:$G$34,"Semi-variabel",B$20:B$34) | C43: =SUMIF($G$20:$G$34,"Tetap",C$20:C$34)+(1-C40)*SUMIF($G$20:$G$34,"Semi-variabel",C$20:C$34) | D43: Rp juta | E43: Tetap dalam rentang produksi relevan
A44: Marjin kontribusi | B44: =B41-B42 | C44: =C41-C42 | D44: Rp juta | E44: Pendapatan – biaya variabel
A45: Rasio marjin kontribusi | B45: =IFERROR(B44/B41,0) | C45: =IFERROR(C44/C41,0) | D45: %
...

Sheet B2 COP dan KPI
A1: Cost of Production (COP) per Unit & Penilaian KPI – model contoh
A2: USD/unit = Biaya (Rp juta) × 1.000.000 ÷ volume basis ÷ kurs rata-rata tahun berjalan
A4: 1. BIAYA PRODUKSI PER UNIT (UNIT COST) | M4: Skala penilaian KPI
A5: Komponen | B5: Basis | C5: Biaya 2024 (Rp juta) | D5: Biaya 2025 (Rp juta) | E5: Volume basis 2024 | F5: Volume basis 2025 | G5: USD/unit 2024 | H5: USD/unit 2025 | I5: Δ USD/unit | J5: Δ% | K5: Penilaian | M5: Skor 5 jika pencapaian ≥ | N5: 1.05
A6: Jasa kontraktor OB | B6: per bcm OB | C6: ='A2 Laba Rugi Contoh'!C17 | D6: ='A2 Laba Rugi Contoh'!D17 | E6: ='A1 Asumsi Contoh'!C16 | F6: ='A1 Asumsi Contoh'!D16 | G6: =IFERROR(C6*1000000/E6/'A1 Asumsi Contoh'!C7,0) | H6: =IFERROR(D6*1000000/F6/'A1 Asumsi Contoh'!D7,0) | I6: =H6-G6 | J6: =IFERROR(I6/ABS(G6),"") | K6: =IF(I6<=0,"Efisien","Naik – review") | M6: Skor 4 jika ≥ | N6: 1
A7: BBM | B7: per bcm OB | C7: ='A2 Laba Rugi Contoh'!C18 | D7: ='A2 Laba Rugi Contoh'!D18 | E7: ='A1 Asumsi Contoh'!C16 | F7: ='A1 Asumsi Contoh'!D16 | G7: =IFERROR(C7*1000000/E7/'A1 Asumsi Contoh'!C7,0) | H7: =IFERROR(D7*1000000/F7/'A1 Asumsi Contoh'!D7,0) | I7: =H7-G7 | J7: =IFERROR(I7/ABS(G7),"") | K7: =IF(I7<=0,"Efisien","Naik – review") | M7: Skor 3 jika ≥ | N7: 0.95
A8: Peledakan | B8: per bcm OB | C8: ='A2 Laba Rugi Contoh'!C19 | D8: ='A2 Laba Rugi Contoh'!D19 | E8: ='A1 Asumsi Contoh'!C16 | F8: ='A1 Asumsi Contoh'!D16 | G8: =IFERROR(C8*1000000/E8/'A1 Asumsi Contoh'!C7,0) | H8: =IFERROR(D8*1000000/F8/'A1 Asumsi Contoh'!D7,0) | I8: =H8-G8 | J8: =IFERROR(I8/ABS(G8),"") | K8: =IF(I8<=0,"Efisien","Naik – review") | M8: Skor 2 jika ≥ | N8: 0.9
A9: Total biaya pengupasan OB per bcm | B9: per bcm OB | C9: ='A2 Laba Rugi Contoh'!C17+'A2 Laba Rugi Contoh'!C18+'A2 Laba Rugi Contoh'!C19 | D9: ='A2 Laba Rugi Contoh'!D17+'A2 Laba Rugi Contoh'!D18+'A2 Laba Rugi Contoh'!D19 | E9: ='A1 Asumsi Contoh'!C16 | F9: ='A1 Asumsi Contoh'!D16 | G9: =IFERROR(C9*1000000/E9/'A1 Asumsi Contoh'!C7,0) | H9: =IFERROR(D9*1000000/F9/'A1 Asumsi Contoh'!D7,0) | I9: =H9-G9 | J9: =IFERROR(I9/ABS(G9),"") | K9: =IF(I9<=0,"Efisien","Naik – review") | M9: Status Hijau jika ≥ | N9: 1
A10: Biaya OB per ton batubara (efek SR) | B10: per ton produksi | C10: ='A2 Laba Rugi Contoh'!C17+'A2 Laba Rugi Contoh'!C18+'A2 Laba Rugi Contoh'!C19 | D10: ='A2 Laba Rugi Contoh'!D17+'A2 Laba Rugi Contoh'!D18+'A2 Laba Rugi Contoh'!D19 | E10: ='A1 Asumsi Contoh'!C14 | F10: ='A1 Asumsi Contoh'!D14 | G10: =IFERROR(C10*1000000/E10/'A1 Asumsi Contoh'!C7,0) | H10: =IFERROR(D10*1000000/F10/'A1 Asumsi Contoh'!D7,0) | I10: =H10-G10 | J10: =IFERROR(I10/ABS(G10),"") | K10: =IF(I10<=0,"Efisien","Naik – review") | M10: Status Kuning jika ≥ | N10: 0.95
A11: Coal getting | B11: per ton produksi | C11: ='A2 Laba Rugi Contoh'!C20 | D11: ='A2 Laba Rugi Contoh'!D20 | E11: ='A1 Asumsi Contoh'!C14 | F11: ='A1 Asumsi Contoh'!D14 | G11: =IFERROR(C11*1000000/E11/'A1 Asumsi Contoh'!C7,0) | H11: =IFERROR(D11*1000000/F11/'A1 Asumsi Contoh'!D7,0) | I11: =H11-G11 | J11: =IFERROR(I11/ABS(G11),"") | K11: =IF(I11<=0,"Efisien","Naik – review") | M11: Batas atas pencapaian | N11: 1.2
A12: Biaya tambang tetap | B12: per ton produksi | C12: ='A2 Laba Rugi Contoh'!C21+'A2 Laba Rugi Contoh'!C22+'A2 Laba Rugi Contoh'!C23+'A2 Laba Rugi Contoh'!C24 | D12: ='A2 Laba Rugi Contoh'!D21+'A2 Laba Rugi Contoh'!D22+'A2 Laba Rugi Contoh'!D23+'A2 Laba Rugi Contoh'!D24 | E12: ='A1 Asumsi Contoh'!C14 | F12: ='A1 Asumsi Contoh'!D14 | G12: =IFERROR(C12*1000000/E12/'A1 Asumsi Contoh'!C7,0) | H12: =IFERROR(D12*1000000/F12/'A1 Asumsi Contoh'!D7,0) | I12: =H12-G12 | J12: =IFERROR(I12/ABS(G12),"") | K12: =IF(I12<=0,"Efisien","Naik – review") | M12: Skor 1 jika < skor 2. Merah jika < Kuning.
A13: TOTAL BIAYA PENAMBANGAN (mining cost) | B13: per ton produksi | C13: ='A2 Laba Rugi Contoh'!C25 | D13: ='A2 Laba Rugi Contoh'!D25 | E13: ='A1 Asumsi Contoh'!C14 | F13: ='A1 Asumsi Contoh'!D14 | G13: =IFERROR(C13*1000000/E13/'A1 Asumsi Contoh'!C7,0) | H13: =IFERROR(D13*1000000/F13/'A1 Asumsi Contoh'!D7,0) | I13: =H13-G13 | J13: =IFERROR(I13/ABS(G13),"") | K13: =IF(I13<=0,"Efisien","Naik – review") | M13: Polaritas Lower: pencapaian = target ÷ aktual
A14: Crushing & pengolahan | B14: per ton produksi | C14: ='A2 Laba Rugi Contoh'!C27 | D14: ='A2 Laba Rugi Contoh'!D27 | E14: ='A1 Asumsi Contoh'!C14 | F14: ='A1 Asumsi Contoh'!D14 | G14: =IFERROR(C14*1000000/E14/'A1 Asumsi Contoh'!C7,0) | H14: =IFERROR(D14*1000000/F14/'A1 Asumsi Contoh'!D7,0) | I14: =H14-G14 | J14: =IFERROR(I14/ABS(G14),"") | K14: =IF(I14<=0,"Efisien","Naik – review") | M14: Polaritas Higher: pencapaian = aktual ÷ target
A15: Hauling (per ton) | B15: per ton produksi | C15: ='A2 Laba Rugi Contoh'!C28 | D15: ='A2 Laba Rugi Contoh'!D28 | E15: ='A1 Asumsi Contoh'!C14 | F15: ='A1 Asumsi Contoh'!D14 | G15: =IFERROR(C15*1000000/E15/'A1 Asumsi Contoh'!C7,0) | H15: =IFERROR(D15*1000000/F15/'A1 Asumsi Contoh'!D7,0) | I15: =H15-G15 | J15: =IFERROR(I15/ABS(G15),"") | K15: =IF(I15<=0,"Efisien","Naik – review")
A16: Hauling (per ton-km) | B16: per ton-km | C16: ='A2 Laba Rugi Contoh'!C28 | D16: ='A2 Laba Rugi Contoh'!D28 | E16: ='A1 Asumsi Contoh'!C14*'A1 Asumsi Contoh'!C17 | F16: ='A1 Asumsi Contoh'!D14*'A1 Asumsi Contoh'!D17 | G16: =IFERROR(C16*1000000/E16/'A1 Asumsi Contoh'!C7,0) | H16: =IFERROR(D16*1000000/F16/'A1 Asumsi Contoh'!D7,0) | I16: =H16-G16 | J16: =IFERROR(I16/ABS(G16),"") | K16: =IF(I16<=0,"Efisien","Naik – review")
A17: Pelabuhan & stockpile | B17: per ton penjualan | C17: ='A2 Laba Rugi Contoh'!C29 | D17: ='A2 Laba Rugi Contoh'!D29 | E17: ='A1 Asumsi Contoh'!C21 | F17: ='A1 Asumsi Contoh'!D21 | G17: =IFERROR(C17*1000000/E17/'A1 Asumsi Contoh'!C7,0) | H17: =IFERROR(D17*1000000/F17/'A1 Asumsi Contoh'!D7,0) | I17: =H17-G17 | J17: =IFERROR(I17/ABS(G17),"") | K17: =IF(I17<=0,"Efisien","Naik – review")
A18: Tongkang & transshipment | B18: per ton penjualan | C18: ='A2 Laba Rugi Contoh'!C30 | D18: ='A2 Laba Rugi Contoh'!D30 | E18: ='A1 Asumsi Contoh'!C21 | F18: ='A1 Asumsi Contoh'!D21 | G18: =IFERROR(C18*1000000/E18/'A1 Asumsi Contoh'!C7,0) | H18: =IFERROR(D18*1000000/F18/'A1 Asumsi Contoh'!D7,0) | I18: =H18-G18 | J18: =IFERROR(I18/ABS(G18),"") | K18: =IF(I18<=0,"Efisien","Naik – review")
A19: Overhead site (termasuk reklamasi) | B19: per ton produksi | C19: ='A2 Laba Rugi Contoh'!C41 | D19: ='A2 Laba Rugi Contoh'!D41 | E19: ='A1 Asumsi Contoh'!C14 | F19: ='A1 Asumsi Contoh'!D14 | G19: =IFERROR(C19*1000000/E19/'A1 Asumsi Contoh'!C7,0) | H19: =IFERROR(D19*1000000/F19/'A1 Asumsi Contoh'!D7,0) | I19: =H19-G19 | J19: =IFERROR(I19/ABS(G19),"") | K19: =IF(I19<=0,"Efisien","Naik – review")
A20: CASH COST FOB (excl. royalti) | B20: per ton penjualan | C20: ='A2 Laba Rugi Contoh'!C25+'A2 Laba Rugi Contoh'!C31+'A2 Laba Rugi Contoh'!C41 | D20: ='A2 Laba Rugi Contoh'!D25+'A2 Laba Rugi Contoh'!D31+'A2 Laba Rugi Contoh'!D41 | E20: ='A1 Asumsi Contoh'!C21 | F20: ='A1 Asumsi Contoh'!D21 | G20: =IFERROR(C20*1000000/E20/'A1 Asumsi Contoh'!C7,0) | H20: =IFERROR(D20*1000000/F20/'A1 Asumsi Contoh'!D7,0) | I20: =H20-G20 | J20: =IFERROR(I20/ABS(G20),"") | K20: =IF(I20<=0,"Efisien","Naik – review")
A21: Royalti | B21: per ton penjualan | C21: ='A2 Laba Rugi Contoh'!C33 | D21: ='A2 Laba Rugi Contoh'!D33 | E21: ='A1 Asumsi Contoh'!C21 | F21: ='A1 Asumsi Contoh'!D21 | G21: =IFERROR(C21*1000000/E21/'A1 Asumsi Contoh'!C7,0) | H21: =IFERROR(D21*1000000/F21/'A1 Asumsi Contoh'!D7,0) | I21: =H21-G21 | J21: =IFERROR(I21/ABS(G21),"") | K21: =IF(I21<=0,"Efisien","Naik – review")
A22: CASH COST FOB (incl. royalti) | B22: per ton penjualan | C22: ='A2 Laba Rugi Contoh'!C25+'A2 Laba Rugi Contoh'!C31+'A2 Laba Rugi Contoh'!C41+'A2 Laba Rugi Contoh'!C33 | D22: ='A2 Laba Rugi Contoh'!D25+'A2 Laba Rugi Contoh'!D31+'A2 Laba Rugi Contoh'!D41+'A2 Laba Rugi Contoh'!D33 | E22: ='A1 Asumsi Contoh'!C21 | F22: ='A1 Asumsi Contoh'!D21 | G22: =IFERROR(C22*1000000/E22/'A1 Asumsi Contoh'!C7,0) | H22: =IFERROR(D22*1000000/F22/'A1 Asumsi Contoh'!D7,0) | I22: =H22-G22 | J22: =IFERROR(I22/ABS(G22),"") | K22: =IF(I22<=0,"Efisien","Naik – review")
A23: Beban penjualan | B23: per ton penjualan | C23: ='A2 Laba Rugi Contoh'!C62 | D23: ='A2 Laba Rugi Contoh'!D62 | E23: ='A1 Asumsi Contoh'!C21 | F23: ='A1 Asumsi Contoh'!D21 | G23: =IFERROR(C23*1000000/E23/'A1 Asumsi Contoh'!C7,0) | H23: =IFERROR(D23*1000000/F23/'A1 Asumsi Contoh'!D7,0) | I23: =H23-G23 | J23: =IFERROR(I23/ABS(G23),"") | K23: =IF(I23<=0,"Efisien","Naik – review")
A24: Beban umum & administrasi (excl. penyusutan) | B24: per ton penjualan | C24: ='A2 Laba Rugi Contoh'!C73-'A2 Laba Rugi Contoh'!C71 | D24: ='A2 Laba Rugi Contoh'!D73-'A2 Laba Rugi Contoh'!D71 | E24: ='A1 Asumsi Contoh'!C21 | F24: ='A1 Asumsi Contoh'!D21 | G24: =IFERROR(C24*1000000/E24/'A1 Asumsi Contoh'!C7,0) | H24: =IFERROR(D24*1000000/F24/'A1 Asumsi Contoh'!D7,0) | I24: =H24-G24 | J24: =IFERROR(I24/ABS(G24),"") | K24: =IF(I24<=0,"Efisien","Naik – review")
A25: TOTAL CASH COST | B25: per ton penjualan | C25: ='A2 Laba Rugi Contoh'!C25+'A2 Laba Rugi Contoh'!C31+'A2 Laba Rugi Contoh'!C41+'A2 Laba Rugi Contoh'!C33+'A2 Laba Rugi Contoh'!C62+'A2 Laba Rugi Contoh'!C73-'A2 Laba Rugi Contoh'!C71 | D25: ='A2 Laba Rugi Contoh'!D25+'A2 Laba Rugi Contoh'!D31+'A2 Laba Rugi Contoh'!D41+'A2 Laba Rugi Contoh'!D33+'A2 Laba Rugi Contoh'!D62+'A2 Laba Rugi Contoh'!D73-'A2 Laba Rugi Contoh'!D71 | E25: ='A1 Asumsi Contoh'!C21 | F25: ='A1 Asumsi Contoh'!D21 | G25: =IFERROR(C25*1000000/E25/'A1 Asumsi Contoh'!C7,0) | H25: =IFERROR(D25*1000000/F25/'A1 Asumsi Contoh'!D7,0) | I25: =H25-G25 | J25: =IFERROR(I25/ABS(G25),"") | K25: =IF(I25<=0,"Efisien","Naik – review")
A26: Penyusutan & amortisasi | B26: per ton penjualan | C26: ='A2 Laba Rugi Contoh'!C46+'A2 Laba Rugi Contoh'!C71 | D26: ='A2 Laba Rugi Contoh'!D46+'A2 Laba Rugi Contoh'!D71 | E26: ='A1 Asumsi Contoh'!C21 | F26: ='A1 Asumsi Contoh'!D21 | G26: =IFERROR(C26*1000000/E26/'A1 Asumsi Contoh'!C7,0) | H26: =IFERROR(D26*1000000/F26/'A1 Asumsi Contoh'!D7,0) | I26: =H26-G26 | J26: =IFERROR(I26/ABS(G26),"") | K26: =IF(I26<=0,"Efisien","Naik – review")
A27: Capex berkelanjutan (aset tetap + pengupasan tangguhan) | B27: per ton penjualan | C27: ='A1 Asumsi Contoh'!C90+'A1 Asumsi Contoh'!C92 | D27: ='A1 Asumsi Contoh'!D90+'A1 Asumsi Contoh'!D92 | E27: ='A1 Asumsi Contoh'!C21 | F27: ='A1 Asumsi Contoh'!D21 | G27: =IFERROR(C27*1000000/E27/'A1 Asumsi Contoh'!C7,0) | H27: =IFERROR(D27*1000000/F27/'A1 Asumsi Contoh'!D7,0) | I27: =H27-G27 | J27: =IFERROR(I27/ABS(G27),"") | K27: =IF(I27<=0,"Efisien","Naik – review")
A28: ALL-IN SUSTAINING COST (AISC) | B28: per ton penjualan | C28: ='A2 Laba Rugi Contoh'!C25+'A2 Laba Rugi Contoh'!C31+'A2 Laba Rugi Contoh'!C41+'A2 Laba Rugi Contoh'!C33+'A2 Laba Rugi Contoh'!C62+'A2 Laba Rugi Contoh'!C73-'A2 Laba Rugi Contoh'!C71+'A1 Asumsi Contoh'!C90+'A1 Asumsi Contoh'!C92 | D28: ='A2 Laba Rugi Contoh'!D25+'A2 Laba Rugi Contoh'!D31+'A2 Laba Rugi Contoh'!D41+'A2 Laba Rugi Contoh'!D33+'A2 Laba Rugi Contoh'!D62+'A2 Laba Rugi Contoh'!D73-'A2 Laba Rugi Contoh'!D71+'A1 Asumsi Contoh'!D90+'A1 Asumsi Contoh'!D92 | E28: ='A1 Asumsi Contoh'!C21 | F28: ='A1 Asumsi Contoh'!D21 | G28: =IFERROR(C28*1000000/E28/'A1 Asumsi Contoh'!C7,0) | H28: =IFERROR(D28*1000000/F28/'A1 Asumsi Contoh'!D7,0) | I28: =H28-G28 | J28: =IFERROR(I28/ABS(G28),"") | K28: =IF(I28<=0,"Efisien","Naik – review")
A29: Harga jual rata-rata (ASP) blended, neto penalti | B29: per ton penjualan | C29: ='A2 Laba Rugi Contoh'!C10+'A2 Laba Rugi Contoh'!C11 | D29: ='A2 Laba Rugi Contoh'!D10+'A2 Laba Rugi Contoh'!D11 | E29: ='A1 Asumsi Contoh'!C21 | F29: ='A1 Asumsi Contoh'!D21 | G29: =IFERROR(C29*1000000/E29/'A1 Asumsi Contoh'!C7,0) | H29: =IFERROR(D29*1000000/F29/'A1 Asumsi Contoh'!D7,0) | I29: =H29-G29 | J29: =IFERROR(I29/ABS(G29),"") | K29: =IF(I29>=0,"Membaik","Menurun – review")
A30: MARJIN KAS PER TON (ASP – total cash cost) | B30: per ton penjualan | C30: =C29-C25 | D30: =D29-D25 | E30: ='A1 Asumsi Contoh'!C21 | F30: ='A1 Asumsi Contoh'!D21 | G30: =IFERROR(C30*1000000/E30/'A1 Asumsi Contoh'!C7,0) | H30: =IFERROR(D30*1000000/F30/'A1 Asumsi Contoh'!D7,0) | I30: =H30-G30 | J30: =IFERROR(I30/ABS(G30),"") | K30: =IF(I30>=0,"Membaik","Menurun – review")
A31: MARJIN AISC PER TON (ASP – AISC) | B31: per ton penjualan | C31: =C29-C28 | D31: =D29-D28 | E31: ='A1 Asumsi Contoh'!C21 | F31: ='A1 Asumsi Contoh'!D21 | G31: =IFERROR(C31*1000000/E31/'A1 Asumsi Contoh'!C7,0) | H31: =IFERROR(D31*1000000/F31/'A1 Asumsi Contoh'!D7,0) | I31: =H31-G31 | J31: =IFERROR(I31/ABS(G31),"") | K31: =IF(I31>=0,"Membaik","Menurun – review")
A32: Catatan: cash cost memakai basis ton penjualan; mining cost memakai basis ton produksi; biaya OB memakai basis bcm. AISC = total cash cost + capex berkelanjutan.
A34: 2. PENILAIAN KPI COST OF PRODUCTION – FY2025
A35: KPI Cost of Production | B35: Satuan | C35: Aktual FY2024 | D35: Aktual FY2025 | E35: Target FY2025 | F35: Polaritas | G35: Pencapaian | H35: Skor (1–5) | I35: Status | J35: Catatan manajemen
A36: Stripping ratio | B36: bcm/t | C36: ='A1 Asumsi Contoh'!C15 | D36: ='A1 Asumsi Contoh'!D15 | E36: 7.5 | F36: Lower | G36: =MIN('B2 COP dan KPI'!$N$11,IF(F36="Lower",IF(D36<=0,'B2 COP dan KPI'!$N$11,E36/D36),IFERROR(D36/E36,0))) | H36: =IF(G36>='B2 COP dan KPI'!$N$5,5,IF(G36>='B2 COP dan KPI'!$N$6,4,IF(G36>='B2 COP dan KPI'!$N$7,3,IF(G36>='B2 COP dan KPI'!$N$8,2,1)))) | I36: =IF(G36>='B2 COP dan KPI'!$N$9,"Hijau",IF(G36>='B2 COP dan KPI'!$N$10,"Kuning","Merah")) | J36: Deviasi dari rencana tambang; SR terlalu rendah bisa tanda high-grading
A37: Biaya pengupasan OB | B37: USD/bcm | C37: =G9 | D37: =H9 | E37: 2.75 | F37: Lower | G37: =MIN('B2 COP dan KPI'!$N$11,IF(F37="Lower",IF(D37<=0,'B2 COP dan KPI'!$N$11,E37/D37),IFERROR(D37/E37,0))) | H37: =IF(G37>='B2 COP dan KPI'!$N$5,5,IF(G37>='B2 COP dan KPI'!$N$6,4,IF(G37>='B2 COP dan KPI'!$N$7,3,IF(G37>='B2 COP dan KPI'!$N$8,2,1)))) | I37: =IF(G37>='B2 COP dan KPI'!$N$9,"Hijau",IF(G37>='B2 COP dan KPI'!$N$10,"Kuning","Merah")) | J37: Tarif kontraktor + BBM + peledakan
A38: Fuel ratio | B38: L/bcm | C38: ='A1 Asumsi Contoh'!C29 | D38: ='A1 Asumsi Contoh'!D29 | E38: 0.92 | F38: Lower | G38: =MIN('B2 COP dan KPI'!$N$11,IF(F38="Lower",IF(D38<=0,'B2 COP dan KPI'!$N$11,E38/D38),IFERROR(D38/E38,0))) | H38: =IF(G38>='B2 COP dan KPI'!$N$5,5,IF(G38>='B2 COP dan KPI'!$N$6,4,IF(G38>='B2 COP dan KPI'!$N$7,3,IF(G38>='B2 COP dan KPI'!$N$8,2,1)))) | I38: =IF(G38>='B2 COP dan KPI'!$N$9,"Hijau",IF(G38>='B2 COP dan KPI'!$N$10,"Kuning","Merah")) | J38: Indikator efisiensi armada & jarak angkut OB
A39: Mining cost per ton produksi | B39: USD/t | C39: =G13 | D39: =H13 | E39: 22 | F39: Lower | G39: =MIN('B2 COP dan KPI'!$N$11,IF(F39="Lower",IF(D39<=0,'B2 COP dan KPI'!$N$11,E39/D39),IFERROR(D39/E39,0))) | H39: =IF(G39>='B2 COP dan KPI'!$N$5,5,IF(G39>='B2 COP dan KPI'!$N$6,4,IF(G39>='B2 COP dan KPI'!$N$7,3,IF(G39>='B2 COP dan KPI'!$N$8,2,1)))) | I39: =IF(G39>='B2 COP dan KPI'!$N$9,"Hijau",IF(G39>='B2 COP dan KPI'!$N$10,"Kuning","Merah")) | J39: Dipengaruhi SR, tarif, BBM, biaya tetap tambang
A40: Hauling cost per ton-km | B40: USD/t-km | C40: =G16 | D40: =H16 | E40: 0.1 | F40: Lower | G40: =MIN('B2 COP dan KPI'!$N$11,IF(F40="Lower",IF(D40<=0,'B2 COP dan KPI'!$N$11,E40/D40),IFERROR(D40/E40,0))) | H40: =IF(G40>='B2 COP dan KPI'!$N$5,5,IF(G40>='B2 COP dan KPI'!$N$6,4,IF(G40>='B2 COP dan KPI'!$N$7,3,IF(G40>='B2 COP dan KPI'!$N$8,2,1)))) | I40: =IF(G40>='B2 COP dan KPI'!$N$9,"Hijau",IF(G40>='B2 COP dan KPI'!$N$10,"Kuning","Merah")) | J40: Kondisi jalan, payload, cycle time
A41: Barging cost per ton | B41: USD/t | C41: =G18 | D41: =H18 | E41: 3.9 | F41: Lower | G41: =MIN('B2 COP dan KPI'!$N$11,IF(F41="Lower",IF(D41<=0,'B2 COP dan KPI'!$N$11,E41/D41),IFERROR(D41/E41,0))) | H41: =IF(G41>='B2 COP dan KPI'!$N$5,5,IF(G41>='B2 COP dan KPI'!$N$6,4,IF(G41>='B2 COP dan KPI'!$N$7,3,IF(G41>='B2 COP dan KPI'!$N$8,2,1)))) | I41: =IF(G41>='B2 COP dan KPI'!$N$9,"Hijau",IF(G41>='B2 COP dan KPI'!$N$10,"Kuning","Merah")) | J41: Tarif tongkang, waktu tunggu, draft sungai
A42: Cash cost FOB excl. royalti | B42: USD/t | C42: =G20 | D42: =H20 | E42: 34 | F42: Lower | G42: =MIN('B2 COP dan KPI'!$N$11,IF(F42="Lower",IF(D42<=0,'B2 COP dan KPI'!$N$11,E42/D42),IFERROR(D42/E42,0))) | H42: =IF(G42>='B2 COP dan KPI'!$N$5,5,IF(G42>='B2 COP dan KPI'!$N$6,4,IF(G42>='B2 COP dan KPI'!$N$7,3,IF(G42>='B2 COP dan KPI'!$N$8,2,1)))) | I42: =IF(G42>='B2 COP dan KPI'!$N$9,"Hijau",IF(G42>='B2 COP dan KPI'!$N$10,"Kuning","Merah")) | J42: KPI utama biaya produksi yang dapat dikendalikan
...

Sheet B3 KPI Cost vs Revenue
A1: Analisa KPI Cost vs Revenue – untuk Penilaian Manajemen (model contoh)
A2: Sumber: A2 Laba Rugi, A3 Neraca, A4 Arus Kas, B2 COP. Target/acuan = input manajemen (sel kuning).
A4: No | B4: KPI | C4: Rumus | D4: Satuan | E4: FY2024 | F4: FY2025 | G4: Polaritas | H4: Acuan / Target | I4: Penilaian FY2025 | J4: Interpretasi untuk manajemen
A5: A. PERTUMBUHAN & "JAWS"
A6: 1 | B6: Pertumbuhan pendapatan | C6: Pendapatan t ÷ t-1 – 1 | D6: % | E6: n/a | F6: ='A2 Laba Rugi Contoh'!D13/'A2 Laba Rugi Contoh'!C13-1 | G6: Higher | H6: 0.02 | I6: =IF(G6="Info","Informasi",IF(G6="Higher",IF(F6>=H6,"Baik","Perlu perbaikan"),IF(F6<=H6,"Baik","Perlu perbaikan"))) | J6: Pisahkan efek volume, harga, kurs (lihat B4).
A7: 2 | B7: Pertumbuhan total biaya | C7: Total biaya t ÷ t-1 – 1 | D7: % | E7: n/a | F7: =('A2 Laba Rugi Contoh'!D49+'A2 Laba Rugi Contoh'!D74-'A2 Laba Rugi Contoh'!D81)/('A2 Laba Rugi Contoh'!C49+'A2 Laba Rugi Contoh'!C74-'A2 Laba Rugi Contoh'!C81)-1 | G7: Lower | H7: =F6 | I7: =IF(G7="Info","Informasi",IF(G7="Higher",IF(F7>=H7,"Baik","Perlu perbaikan"),IF(F7<=H7,"Baik","Perlu perbaikan"))) | J7: Target: biaya tumbuh lebih lambat dari pendapatan.
A8: 3 | B8: Jaws ratio | C8: Growth pendapatan – growth biaya | D8: pp | E8: n/a | F8: =F6-F7 | G8: Higher | H8: 0 | I8: =IF(G8="Info","Informasi",IF(G8="Higher",IF(F8>=H8,"Baik","Perlu perbaikan"),IF(F8<=H8,"Baik","Perlu perbaikan"))) | J8: Positif = pendapatan tumbuh lebih cepat dari biaya (leverage operasi sehat).
A9: B. RASIO BIAYA TERHADAP PENDAPATAN
A10: 4 | B10: Rasio total biaya thd pendapatan | C10: (BPP + beban usaha + bunga) ÷ pendapatan | D10: % | E10: =('A2 Laba Rugi Contoh'!C49+'A2 Laba Rugi Contoh'!C74-'A2 Laba Rugi Contoh'!C81)/'A2 Laba Rugi Contoh'!C13 | F10: =('A2 Laba Rugi Contoh'!D49+'A2 Laba Rugi Contoh'!D74-'A2 Laba Rugi Contoh'!D81)/'A2 Laba Rugi Contoh'!D13 | G10: Lower | H10: 0.8 | I10: =IF(G10="Info","Informasi",IF(G10="Higher",IF(F10>=H10,"Baik","Perlu perbaikan"),IF(F10<=H10,"Baik","Perlu perbaikan"))) | J10: Setiap Rp100 pendapatan menyerap Rp x biaya.
A11: 5 | B11: Rasio BPP thd pendapatan | C11: BPP ÷ pendapatan | D11: % | E11: ='A2 Laba Rugi Contoh'!C49/'A2 Laba Rugi Contoh'!C13 | F11: ='A2 Laba Rugi Contoh'!D49/'A2 Laba Rugi Contoh'!D13 | G11: Lower | H11: 0.72 | I11: =IF(G11="Info","Informasi",IF(G11="Higher",IF(F11>=H11,"Baik","Perlu perbaikan"),IF(F11<=H11,"Baik","Perlu perbaikan"))) | J11: Kebalikan dari marjin laba kotor.
A12: 6 | B12: Rasio beban usaha thd pendapatan | C12: (Penjualan + G&A) ÷ pendapatan | D12: % | E12: ='A2 Laba Rugi Contoh'!C74/'A2 Laba Rugi Contoh'!C13 | F12: ='A2 Laba Rugi Contoh'!D74/'A2 Laba Rugi Contoh'!D13 | G12: Lower | H12: 0.07 | I12: =IF(G12="Info","Informasi",IF(G12="Higher",IF(F12>=H12,"Baik","Perlu perbaikan"),IF(F12<=H12,"Baik","Perlu perbaikan"))) | J12: Efisiensi overhead non-produksi.
A13: 7 | B13: Royalti thd pendapatan | C13: Royalti ÷ pendapatan | D13: % | E13: ='A2 Laba Rugi Contoh'!C33/'A2 Laba Rugi Contoh'!C13 | F13: ='A2 Laba Rugi Contoh'!D33/'A2 Laba Rugi Contoh'!D13 | G13: Lower | H13: 0.07 | I13: =IF(G13="Info","Informasi",IF(G13="Higher",IF(F13>=H13,"Baik","Perlu perbaikan"),IF(F13<=H13,"Baik","Perlu perbaikan"))) | J13: Tidak dapat dikendalikan – mengikuti harga & regulasi.
A14: C. PROFITABILITAS
A15: 8 | B15: Marjin laba kotor | C15: Laba kotor ÷ pendapatan | D15: % | E15: ='A2 Laba Rugi Contoh'!C52 | F15: ='A2 Laba Rugi Contoh'!D52 | G15: Higher | H15: 0.28 | I15: =IF(G15="Info","Informasi",IF(G15="Higher",IF(F15>=H15,"Baik","Perlu perbaikan"),IF(F15<=H15,"Baik","Perlu perbaikan")))
A16: 9 | B16: EBITDA | C16: Laba usaha + D&A | D16: Rp juta | E16: ='A2 Laba Rugi Contoh'!C93 | F16: ='A2 Laba Rugi Contoh'!D93 | G16: Higher | H16: 3000000 | I16: =IF(G16="Info","Informasi",IF(G16="Higher",IF(F16>=H16,"Baik","Perlu perbaikan"),IF(F16<=H16,"Baik","Perlu perbaikan"))) | J16: Ukuran kas operasi sebelum modal kerja, pajak & bunga.
A17: 10 | B17: Marjin EBITDA | C17: EBITDA ÷ pendapatan | D17: % | E17: ='A2 Laba Rugi Contoh'!C94 | F17: ='A2 Laba Rugi Contoh'!D94 | G17: Higher | H17: 0.28 | I17: =IF(G17="Info","Informasi",IF(G17="Higher",IF(F17>=H17,"Baik","Perlu perbaikan"),IF(F17<=H17,"Baik","Perlu perbaikan")))
A18: 11 | B18: EBITDA per ton | C18: EBITDA ÷ ton jual ÷ kurs | D18: USD/t | E18: ='A2 Laba Rugi Contoh'!C93*1000000/'A1 Asumsi Contoh'!C21/'A1 Asumsi Contoh'!C7 | F18: ='A2 Laba Rugi Contoh'!D93*1000000/'A1 Asumsi Contoh'!D21/'A1 Asumsi Contoh'!D7 | G18: Higher | H18: 16 | I18: =IF(G18="Info","Informasi",IF(G18="Higher",IF(F18>=H18,"Baik","Perlu perbaikan"),IF(F18<=H18,"Baik","Perlu perbaikan"))) | J18: Pembanding antar-perusahaan yang netral skala.
A19: 12 | B19: Marjin laba usaha | C19: Laba usaha ÷ pendapatan | D19: % | E19: ='A2 Laba Rugi Contoh'!C77 | F19: ='A2 Laba Rugi Contoh'!D77 | G19: Higher | H19: 0.22 | I19: =IF(G19="Info","Informasi",IF(G19="Higher",IF(F19>=H19,"Baik","Perlu perbaikan"),IF(F19<=H19,"Baik","Perlu perbaikan")))
A20: 13 | B20: Marjin laba bersih | C20: Laba bersih ÷ pendapatan | D20: % | E20: ='A2 Laba Rugi Contoh'!C90 | F20: ='A2 Laba Rugi Contoh'!D90 | G20: Higher | H20: 0.16 | I20: =IF(G20="Info","Informasi",IF(G20="Higher",IF(F20>=H20,"Baik","Perlu perbaikan"),IF(F20<=H20,"Baik","Perlu perbaikan")))
A21: D. HARGA vs BIAYA PER TON
A22: 14 | B22: ASP blended | C22: Penjualan batubara neto ÷ ton | D22: USD/t | E22: ='B2 COP dan KPI'!G29 | F22: ='B2 COP dan KPI'!H29 | G22: Higher | H22: 58 | I22: =IF(G22="Info","Informasi",IF(G22="Higher",IF(F22>=H22,"Baik","Perlu perbaikan"),IF(F22<=H22,"Baik","Perlu perbaikan")))
A23: 15 | B23: Realisasi harga ekspor vs indeks | C23: ASP ekspor ÷ indeks acuan | D23: % | E23: ='A1 Asumsi Contoh'!C9/'A1 Asumsi Contoh'!C8 | F23: ='A1 Asumsi Contoh'!D9/'A1 Asumsi Contoh'!D8 | G23: Higher | H23: 0.95 | I23: =IF(G23="Info","Informasi",IF(G23="Higher",IF(F23>=H23,"Baik","Perlu perbaikan"),IF(F23<=H23,"Baik","Perlu perbaikan"))) | J23: Mengukur kualitas pemasaran & spesifikasi produk.
A24: 16 | B24: Total cash cost | C24: Lihat B2 | D24: USD/t | E24: ='B2 COP dan KPI'!G25 | F24: ='B2 COP dan KPI'!H25 | G24: Lower | H24: 43 | I24: =IF(G24="Info","Informasi",IF(G24="Higher",IF(F24>=H24,"Baik","Perlu perbaikan"),IF(F24<=H24,"Baik","Perlu perbaikan")))
A25: 17 | B25: Marjin kas per ton | C25: ASP – total cash cost | D25: USD/t | E25: ='B2 COP dan KPI'!G30 | F25: ='B2 COP dan KPI'!H30 | G25: Higher | H25: 15 | I25: =IF(G25="Info","Informasi",IF(G25="Higher",IF(F25>=H25,"Baik","Perlu perbaikan"),IF(F25<=H25,"Baik","Perlu perbaikan")))
A26: 18 | B26: Harga impas kas (cash breakeven) | C26: (Total cash cost + bunga) per ton | D26: USD/t | E26: ='B2 COP dan KPI'!G25-'A2 Laba Rugi Contoh'!C81*1000000/'A1 Asumsi Contoh'!C21/'A1 Asumsi Contoh'!C7 | F26: ='B2 COP dan KPI'!H25-'A2 Laba Rugi Contoh'!D81*1000000/'A1 Asumsi Contoh'!D21/'A1 Asumsi Contoh'!D7 | G26: Lower | H26: 45 | I26: =IF(G26="Info","Informasi",IF(G26="Higher",IF(F26>=H26,"Baik","Perlu perbaikan"),IF(F26<=H26,"Baik","Perlu perbaikan"))) | J26: Harga minimum agar kas operasi tidak negatif.
A27: 19 | B27: Margin of safety harga | C27: (ASP – harga impas) ÷ ASP | D27: % | E27: =IFERROR(('B2 COP dan KPI'!G29-E26)/'B2 COP dan KPI'!G29,0) | F27: =IFERROR(('B2 COP dan KPI'!H29-F26)/'B2 COP dan KPI'!H29,0) | G27: Higher | H27: 0.2 | I27: =IF(G27="Info","Informasi",IF(G27="Higher",IF(F27>=H27,"Baik","Perlu perbaikan"),IF(F27<=H27,"Baik","Perlu perbaikan"))) | J27: Ketahanan terhadap penurunan harga batubara.
A28: 20 | B28: Degree of operating leverage (DOL) | C28: %Δ laba usaha ÷ %Δ pendapatan | D28: x | E28: n/a | F28: =IFERROR(('A2 Laba Rugi Contoh'!D76/'A2 Laba Rugi Contoh'!C76-1)/F6,0) | G28: Info | I28: =IF(G28="Info","Informasi",IF(G28="Higher",IF(F28>=H28,"Baik","Perlu perbaikan"),IF(F28<=H28,"Baik","Perlu perbaikan"))) | J28: DOL tinggi = laba sangat sensitif thd perubahan pendapatan.
A29: E. KAS, LEVERAGE & IMBAL HASIL
A30: 21 | B30: Interest coverage | C30: EBITDA ÷ beban bunga | D30: x | E30: =IFERROR('A2 Laba Rugi Contoh'!C93/-'A2 Laba Rugi Contoh'!C81,0) | F30: =IFERROR('A2 Laba Rugi Contoh'!D93/-'A2 Laba Rugi Contoh'!D81,0) | G30: Higher | H30: 5 | I30: =IF(G30="Info","Informasi",IF(G30="Higher",IF(F30>=H30,"Baik","Perlu perbaikan"),IF(F30<=H30,"Baik","Perlu perbaikan")))
A31: 22 | B31: Konversi kas (cash conversion) | C31: CFO ÷ EBITDA | D31: % | E31: ='A4 Arus Kas Contoh'!C25/'A2 Laba Rugi Contoh'!C93 | F31: ='A4 Arus Kas Contoh'!D25/'A2 Laba Rugi Contoh'!D93 | G31: Higher | H31: 0.8 | I31: =IF(G31="Info","Informasi",IF(G31="Higher",IF(F31>=H31,"Baik","Perlu perbaikan"),IF(F31<=H31,"Baik","Perlu perbaikan"))) | J31: Kualitas laba – seberapa banyak EBITDA menjadi kas.
A32: 23 | B32: ROE | C32: Laba bersih ÷ ekuitas rata-rata | D32: % | E32: ='A2 Laba Rugi Contoh'!C89/(('A3 Neraca Contoh'!D51+'A3 Neraca Contoh'!C51)/2) | F32: ='A2 Laba Rugi Contoh'!D89/(('A3 Neraca Contoh'!E51+'A3 Neraca Contoh'!D51)/2) | G32: Higher | H32: 0.2 | I32: =IF(G32="Info","Informasi",IF(G32="Higher",IF(F32>=H32,"Baik","Perlu perbaikan"),IF(F32<=H32,"Baik","Perlu perbaikan")))
